Workbook
Name Accidents: 'Data Fields'!$B$2:$B$14
Name Dangerous_Occurrence: 'Data Fields'!$B$31:$B$42
Name Near_Miss: 'Data Fields'!$B$16:$B$29

Sheet Main Sheet data
A1: Reference Number | B1: Reported Date | C1: Incident Date | D1: Incident Time | E1: Site | F1: Address | G1: Reported By | H1: Team | I1: Person Involved | J1: Company Name | K1: Company Address | L1: Incident | M1: Accident/Near Miss/Dangerous Occurrence | N1: Category | O1: Sub Category | P1: Part of the Body | Q1: Details of Incident | R1: RIDDOR | S1: Insurers Advised | T1: Tracking and Further Actions | U1: Time Lost Yes/No | V1: Amount of Time Lost | W1: IP Go to Hospital | X1: If Yes, Give Details | Y1: Gallagher Insurance Reference | Z1: Open/Closed | AA1: Date Closed | AB1: Number in 2024
B2: ='Incident Report'!H3 -> 0 | C2: ='Incident Report'!E17 -> 0 | D2: ='Incident Report'!E18 -> 0 | E2: ='Incident Report'!C2 -> 0 | F2: ='Incident Report'!E15 -> 0 | G2: ='Incident Report'!B3 -> 0 | H2: ='Incident Report'!B4 -> 0 | I2: ='Incident Report'!E9 -> 0 | J2: ='Incident Report'!E11 -> 0 | K2: ='Incident Report'!E12 -> 0 | M2: ='Incident Report'!E6 -> 0 | N2: ='Incident Report'!E7 -> 0 | P2: ='Incident Report'!E25 | R2: ='Incident Report'!H27 -> 0 | U2: ='Incident Report'!B29 | V2: ='Incident Report'!E29 -> 0 | W2: ='Incident Report'!B31 | X2: ='Incident Report'!E31 -> 0 | AA2: =IF('Incident Report'!H41="", "", 'Incident Report'!H41)

Sheet Data Fields
A1: Team | B1: Accidents | D1: Part of Body | E1: Days
A2: 1 | B2: Slips, Trips, and Falls | C2: YES | D2: N/A | E2: 1
A3: 2 | B3: Falls from Height | C3: NO | D3: Medical | E3: 2
A4: 3 | B4: Manual Handling | C4: N/A | D4: Head | E4: 3
A5: Head Office | B5: Struck by Moving or Falling Objects | D5: Eye (S) | E5: 4
B6: Contact with Moving Machinery | D6: Face | E6: 5
B7: Struck by Moving Vehicles | D7: Nose | E7: 6
B8: Electric Shock or Burns | D8: Ears | E8: 7
B9: Exposure to Harmful Substances | D9: Neck | E9: 8
B10: Collapse of Structures | D10: Shoulder | E10: 9
B11: Environmental | D11: Arm | E11: 10
B12: Medical Emergency (eg Stroke, Heart) | D12: Wrist | E12: 11
B13: Vehicle/Plant-Related (eg Crash) | D13: Hand | E13: 12
B14: Incorrect / No PPE | D14: Fingers | E14: 14
B15: Near_Miss | D15: Torso | E15: 15
B16: Falls from Height (Prevented) | D16: Ribs | E16: 16
B17: Slips, Trips, and Falls (Prevented) | D17: Back | E17: 17
... B22: Equipment or Tool Malfunctions (Prevented) | D22: Toes | E22: 22
B23: Fire or Explosion (Prevented) | E23: 23
B24: Exposure to Harmful Substances (Prevented) | E24: 24
B25: Crane or Lifting Equipment Incidents (Prevented) | E25: 25
B26: Signing lighting and guarding, security (Improved) | E26: 26
B27: Environmental (Prevented) | E27: 27
B28: Manual Handling Injuries (Prevented) | E28: 28
B29: Incorrect / No PPE (Prevented) | E29: 29
B30: Dangerous_Occurance | E30: 30
B31: Escape of Substances (eg Asbestos) (Reported under RIDDOR) | E31: 31
B32: Pressure Systems (Reported under RIDDOR) | E32: 32
B33: Transport-Related Incidents (Overturning) (Reported under RIDDOR) | E33: 33
B34: Security (Intruder) & Safe Guarding | E34: 34
... B42: Flood / Risk of Drowning | E42: 42
E43: 43
E44: 44
E45: 45
E46: 46
E47: 47
E48: 48
E49: 49
E50: 50
E51: 51
...

Sheet Incident Report
B1: INCIDENT REPORT FORM (03-045-04) | G1: Issue:
B2: Project: | G2: Job No:
A3: Prepared By: | D3: Received by: | G3: Date:
A4: Team: | D4: Distribution:
K5: Accident | L5: An event that results in injury or ill health
A6: Type of Incident | K6: Near Miss | L6: An event that could have caused harm or damage but did not
A7: Category of Incident | K7: Dangerous Occurrence | L7: Specific type of incident or event that has the potential to cause significant harm to people, property, or the environment, even if no harm actually occurs.
A9: 1. Name of person who was involved in the incident
A10: Address of person who was involved in the incident
A11: Name of Employer
A12: Address of Employer
A13: Telephone Number of Employer
A15: 2. Site Address (including Postcode)
A16: 3. Location of the incident
A17: 4a. Date of incident (DD/MM/YYYY)
A18: 4b. Time of incident (24 hour clock)
A20: 5. Description of Incident: (Please take a photograph of the injury or incident if possible)
A22: Insert Photographs here: | K22: To Insert a Photo into a Cell: Click on Insert Click on Pictures Place in Cell From this Device Select Photo
A25: 6. Injured Part of Body | E25: =IF(OR(E6="Near_Miss", E6="Dangerous_Occurrence"), "N/A", "") | AH25: Leg
A27: 7. Was the person injured | B27: =IF(OR(E6="Near_Miss", E6="Dangerous_Occurrence"), "N/A", "") | D27: 8. If yes has the accident book been completed | E27: =IF(OR(E6="Near_Miss", E6="Dangerous_Occurrence"), "N/A", "") | G27: 9. Was the incident RIDDOR reportable
A29: 10. Was any time lost due to the incident | B29: =IF(OR(E6="Near_Miss", E6="Dangerous_Occurrence"), "N/A", "") | D29: If Yes, amount of time lost (days)
A31: 11. Did the Injured Person (IP) go to hospital | B31: =IF(OR(E6="Near_Miss", E6="Dangerous_Occurrence"), "N/A", "") | D31: If Yes, please give details
A32: 12. Did the Injured Person (IP) see a GP | B32: =IF(OR(E6="Near_Miss", E6="Dangerous_Occurrence"), "N/A", "") | D32: If Yes, please give details
A34: 13. Details of any action taken as a result of matters identified in item 5 above:
A35: 14. Details of any further action considered necessary:
A37: 17. Name of person making the report: | F37: Date report handed to Line Manager:
A38: 17. Position of person making the report:
A39: Signature:
A41: 18. Name of person signing off the incident: | F41: Date incident signed off:
A42: 17. Position of person signing off the incident:
A43: Signature:

Sheet Types of Dangerous Occurences
A2: Examples of Dangerous Occurrences under RIDDOR
A3: The types of dangerous occurrences that must be reported include, but are not limited to:
A6: 1. Collapse, Overturning, or Failure
A7: Collapse of a scaffold above 5 meters in height.
A8: Failure of lifting equipment, cranes, or hoists.
A9: 2. Explosion, Fire, or Uncontrolled Release
A10: Explosion or fire causing work to stop for over 24 hours.
A11: Uncontrolled release of a dangerous substance, such as toxic gas or chemicals.
A12: 3. Electrical Incidents
A13: Incidents causing electrical plant or equipment to catch fire or malfunction dangerously.
A14: 4. Structural Failures
A15: Collapse or partial collapse of any structure under construction, use, or demolition.
... A24: Railway incidents, such as collisions or derailments.
